<mujoco model="kinova_allegro_scene">
  <compiler angle="radian"/>

  <option impratio="10" integrator="implicitfast" cone="elliptic"/>

  <size nkey="1"/>

  <visual>
    <global azimuth="150" elevation="-25"/>
    <headlight ambient="0.15 0.15 0.15" diffuse="0.6 0.6 0.6" specular="0 0 0"/>
    <rgba haze="0.15 0.25 0.35 1"/>
  </visual>

  <statistic meansize="0.05" extent="1" center="0.3 0 0.6"/>

  <default>
    <default class="kinova_visual">
      <geom type="mesh" contype="0" conaffinity="0" group="2" rgba="0.75294 0.75294 0.75294 1"/>
    </default>
    <default class="kinova_collision">
      <geom type="mesh" group="3"/>
    </default>
    <default class="large_actuator">
      <general forcerange="-105 105" biastype="affine" gainprm="2000" biasprm="0 -2000 -100"/>
    </default>
    <default class="small_actuator">
      <general forcerange="-52 52" biastype="affine" gainprm="500" biasprm="0 -500 -50"/>
    </default>
    <default class="allegro_right">
      <joint damping="0.1"/>
      <geom density="800"/>
      <general biastype="affine" biasprm="0 -1"/>
      <default class="allegro_visual">
        <geom type="mesh" contype="0" conaffinity="0" group="2" material="allegro_black"/>
      </default>
      <default class="allegro_collision">
        <geom type="box" contype="2" conaffinity="2" group="3"/>
        <default class="palm_collision">
          <geom size="0.0204 0.0565 0.0475"/>
        </default>
        <default class="base_collision">
          <geom size="0.0098 0.01375 0.0082"/>
          <default class="thumb_base_collision">
            <geom size="0.0179 0.017 0.02275"/>
          </default>
        </default>
        <default class="proximal_collision">
          <geom size="0.0098 0.01375 0.027"/>
          <default class="thumb_proximal_collision">
            <geom size="0.0098 0.01375 0.00885"/>
          </default>
        </default>
        <default class="medial_collision">
          <geom size="0.0098 0.01375 0.0192"/>
          <default class="thumb_medial_collision">
            <geom size="0.0098 0.01375 0.0257"/>
          </default>
        </default>
        <default class="distal_collision">
          <geom size="0.0098 0.01375 0.008"/>
          <default class="thumb_distal_collision">
            <geom size="0.0098 0.01375 0.0157"/>
          </default>
        </default>
        <default class="fingertip_collision">
          <geom size="0.012 0.01 0" type="capsule"/>
          <default class="thumbtip_collision">
            <geom size="0.012 0.008 0"/>
          </default>
        </default>
      </default>
      <default class="base">
        <joint range="-0.47 0.47"/>
        <general ctrlrange="-0.47 0.47"/>
      </default>
      <default class="proximal">
        <joint range="-0.196 1.61"/>
        <general ctrlrange="-0.196 1.61"/>
      </default>
      <default class="medial">
        <joint range="-0.174 1.709"/>
        <general ctrlrange="-0.174 1.709"/>
      </default>
      <default class="distal">
        <joint range="-0.227 1.618"/>
        <general ctrlrange="-0.227 1.618"/>
      </default>
      <default class="thumb_base">
        <joint range="0.263 1.396"/>
        <general ctrlrange="0.263 1.396"/>
      </default>
      <default class="thumb_proximal">
        <joint range="-0.105 1.163"/>
        <general ctrlrange="-0.105 1.163"/>
      </default>
      <default class="thumb_medial">
        <joint range="-0.189 1.644"/>
        <general ctrlrange="-0.189 1.644"/>
      </default>
      <default class="thumb_distal">
        <joint range="-0.162 1.719"/>
        <general ctrlrange="-0.162 1.719"/>
      </default>
    </default>
    <default class="obstacle">
      <geom contype="4" conaffinity="7" rgba="0.6 0.15 0.15 0.6"/>
    </default>
  </default>

  <asset>
    <texture type="skybox" colorspace="auto" builtin="gradient" rgb1="0.3 0.5 0.7" rgb2="0 0 0" width="512" height="3072"/>
    <texture type="2d" colorspace="auto" name="groundplane" builtin="checker" mark="edge" rgb1="0.2 0.3 0.4" rgb2="0.1 0.2 0.3" markrgb="0.8 0.8 0.8" width="300" height="300"/>
    <material name="allegro_black" rgba="0.2 0.2 0.2 1"/>
    <material name="allegro_white" rgba="0.9 0.9 0.9 1"/>
    <material name="groundplane" texture="groundplane" texuniform="true" texrepeat="5 5" reflectance="0.2"/>
    <material name="rack_metal" shininess="0.3" rgba="0.35 0.35 0.4 1"/>
    <material name="cable_tray" rgba="0.25 0.25 0.3 0.8"/>
    <material name="target_obj" rgba="0.2 0.7 0.3 1"/>
    <mesh name="base_link" content_type="model/stl" file="assets/kinova/base_link.stl"/>
    <mesh name="shoulder_link" content_type="model/stl" file="assets/kinova/shoulder_link.stl"/>
    <mesh name="half_arm_1_link" content_type="model/stl" file="assets/kinova/half_arm_1_link.stl"/>
    <mesh name="half_arm_2_link" content_type="model/stl" file="assets/kinova/half_arm_2_link.stl"/>
    <mesh name="forearm_link" content_type="model/stl" file="assets/kinova/forearm_link.stl"/>
    <mesh name="spherical_wrist_1_link" content_type="model/stl" file="assets/kinova/spherical_wrist_1_link.stl"/>
    <mesh name="spherical_wrist_2_link" content_type="model/stl" file="assets/kinova/spherical_wrist_2_link.stl"/>
    <mesh name="bracelet_with_vision_link" content_type="model/stl" file="assets/kinova/bracelet_with_vision_link.stl"/>
    <mesh name="allegro_base_link" content_type="model/stl" file="assets/allegro/base_link.stl"/>
    <mesh name="link_0.0" content_type="model/stl" file="assets/allegro/link_0.0.stl"/>
    <mesh name="link_1.0" content_type="model/stl" file="assets/allegro/link_1.0.stl"/>
    <mesh name="link_2.0" content_type="model/stl" file="assets/allegro/link_2.0.stl"/>
    <mesh name="link_3.0" content_type="model/stl" file="assets/allegro/link_3.0.stl"/>
    <mesh name="link_3.0_tip" content_type="model/stl" file="assets/allegro/link_3.0_tip.stl"/>
    <mesh name="link_12.0_right" content_type="model/stl" file="assets/allegro/link_12.0_right.stl"/>
    <mesh name="link_13.0" content_type="model/stl" file="assets/allegro/link_13.0.stl"/>
    <mesh name="link_14.0" content_type="model/stl" file="assets/allegro/link_14.0.stl"/>
    <mesh name="link_15.0" content_type="model/stl" file="assets/allegro/link_15.0.stl"/>
    <mesh name="link_15.0_tip" content_type="model/stl" file="assets/allegro/link_15.0_tip.stl"/>
  </asset>

  <worldbody>
    <geom name="floor" size="0 0 0.05" type="plane" material="groundplane"/>
    <light pos="0.5 0 1.5" dir="0 0 -1" type="directional"/>
    <light pos="-0.5 0.5 1" dir="0 0 -1" diffuse="0.3 0.3 0.3"/>
    <body name="base_link" pos="0 0 0.5">
      <inertial pos="-0.000648 -0.000166 0.084487" quat="0.999294 0.00139618 -0.0118387 0.035636" mass="1.697" diaginertia="0.00462407 0.00449437 0.00207755"/>
      <geom class="kinova_visual" mesh="base_link"/>
      <geom class="kinova_collision" mesh="base_link"/>
      <body name="shoulder_link" pos="0 0 0.15643" quat="0 1 0 0">
        <inertial pos="-2.3e-05 -0.010364 -0.07336" quat="0.707051 0.0451246 -0.0453544 0.704263" mass="1.3773" diaginertia="0.00488868 0.00457 0.00135132"/>
        <joint name="joint_1" pos="0 0 0" axis="0 0 1" range="-6.28318 6.28318"/>
        <geom class="kinova_visual" mesh="shoulder_link"/>
        <geom class="kinova_collision" mesh="shoulder_link"/>
        <body name="half_arm_1_link" pos="0 0.005375 -0.12838" quat="0.707107 0.707107 0 0">
          <inertial pos="-4.4e-05 -0.09958 -0.013278" quat="0.482348 0.516286 -0.516862 0.483366" mass="1.1636" diaginertia="0.0113017 0.011088 0.00102532"/>
          <joint name="joint_2" pos="0 0 0" axis="0 0 1" range="-2.2497 2.2497"/>
          <geom class="kinova_visual" mesh="half_arm_1_link"/>
          <geom class="kinova_collision" mesh="half_arm_1_link"/>
          <body name="half_arm_2_link" pos="0 -0.21038 -0.006375" quat="0.707107 -0.707107 0 0">
            <inertial pos="-4.4e-05 -0.006641 -0.117892" quat="0.706144 0.0213722 -0.0209128 0.707437" mass="1.1636" diaginertia="0.0111633 0.010932 0.00100671"/>
            <joint name="joint_3" pos="0 0 0" axis="0 0 1" range="-6.28318 6.28318"/>
            <geom class="kinova_visual" mesh="half_arm_2_link"/>
            <geom class="kinova_collision" mesh="half_arm_2_link"/>
            <body name="forearm_link" pos="0 0.006375 -0.21038" quat="0.707107 0.707107 0 0">
              <inertial pos="-1.8e-05 -0.075478 -0.015006" quat="0.483678 0.515961 -0.515859 0.483455" mass="0.9302" diaginertia="0.00834839 0.008147 0.000598606"/>
              <joint name="joint_4" pos="0 0 0" axis="0 0 1" range="-2.5796 2.5796"/>
              <geom class="kinova_visual" mesh="forearm_link"/>
              <geom class="kinova_collision" mesh="forearm_link"/>
              <body name="spherical_wrist_1_link" pos="0 -0.20843 -0.006375" quat="0.707107 -0.707107 0 0">
                <inertial pos="1e-06 -0.009432 -0.063883" quat="0.703558 0.0707492 -0.0707492 0.703558" mass="0.6781" diaginertia="0.00165901 0.001596 0.000346988"/>
                <joint name="joint_5" pos="0 0 0" axis="0 0 1" range="-6.28318 6.28318"/>
                <geom class="kinova_visual" mesh="spherical_wrist_1_link"/>
                <geom class="kinova_collision" mesh="spherical_wrist_1_link"/>
                <body name="spherical_wrist_2_link" pos="0 0.00017505 -0.10593" quat="0.707107 0.707107 0 0">
                  <inertial pos="1e-06 -0.045483 -0.00965" quat="0.44426 0.550121 -0.550121 0.44426" mass="0.6781" diaginertia="0.00170087 0.001641 0.00035013"/>
                  <joint name="joint_6" pos="0 0 0" axis="0 0 1" range="-2.0996 2.0996"/>
                  <geom class="kinova_visual" mesh="spherical_wrist_2_link"/>
                  <geom class="kinova_collision" mesh="spherical_wrist_2_link"/>
                  <body name="bracelet_link" pos="0 -0.10593 -0.00017505" quat="0.707107 -0.707107 0 0">
                    <inertial pos="0.000281 0.011402 -0.029798" quat="0.394358 0.596779 -0.577293 0.393789" mass="0.5" diaginertia="0.000657336 0.000587019 0.000320645"/>
                    <joint name="joint_7" pos="0 0 0" axis="0 0 1" range="-6.28318 6.28318"/>
                    <geom class="kinova_visual" mesh="bracelet_with_vision_link"/>
                    <geom class="kinova_collision" mesh="bracelet_with_vision_link"/>
                    <site name="pinch_site" pos="0 0 -0.061525" quat="0 1 0 0"/>
                    <body name="palm" childclass="allegro_right" pos="0.01 0 -0.161525" quat="0 1 0 0">
                      <geom class="allegro_visual" mesh="allegro_base_link"/>
                      <geom class="palm_collision" pos="-0.0093 0 -0.0475" mass="0"/>
                      <body name="ff_base" pos="0 0.0435 -0.001542" quat="0.999048 -0.0436194 0 0">
                        <joint name="ffj0" class="base" pos="0 0 0" axis="0 0 1"/>
                        <geom class="allegro_visual" mesh="link_0.0"/>
                        <geom class="base_collision" pos="0 0 0.0082" mass="0"/>
                        <body name="ff_proximal" pos="0 0 0.0164">
                          <joint name="ffj1" class="proximal" pos="0 0 0" axis="0 1 0"/>
                          <geom class="allegro_visual" mesh="link_1.0"/>
                          <geom class="proximal_collision" pos="0 0 0.027" mass="0"/>
                          <body name="ff_medial" pos="0 0 0.054">
                            <joint name="ffj2" class="medial" pos="0 0 0" axis="0 1 0"/>
                            <geom class="allegro_visual" mesh="link_2.0"/>
                            <geom class="medial_collision" pos="0 0 0.0192" mass="0"/>
                            <body name="ff_distal" pos="0 0 0.0384">
                              <joint name="ffj3" class="distal" pos="0 0 0" axis="0 1 0"/>
                              <geom class="allegro_visual" mesh="link_3.0"/>
                              <geom class="distal_collision" pos="0 0 0.008" mass="0"/>
                              <body name="ff_tip">
                                <geom class="allegro_visual" pos="0 0 0.0267" material="allegro_white" mesh="link_3.0_tip"/>
                                <geom class="fingertip_collision" pos="0 0 0.019" mass="0"/>
                                <site name="ff_grasp" pos="0 0 0.029" size="0.003" rgba="1 0 0 1"/>
                              </body>
                            </body>
                          </body>
                        </body>
                      </body>
                      <body name="mf_base" pos="0 0 0.0007">
                        <joint name="mfj0" class="base" pos="0 0 0" axis="0 0 1"/>
                        <geom class="allegro_visual" mesh="link_0.0"/>
                        <geom class="base_collision" pos="0 0 0.0082" mass="0"/>
                        <body name="mf_proximal" pos="0 0 0.0164">
                          <joint name="mfj1" class="proximal" pos="0 0 0" axis="0 1 0"/>
                          <geom class="allegro_visual" mesh="link_1.0"/>
                          <geom class="proximal_collision" pos="0 0 0.027" mass="0"/>
                          <body name="mf_medial" pos="0 0 0.054">
                            <joint name="mfj2" class="medial" pos="0 0 0" axis="0 1 0"/>
                            <geom class="allegro_visual" mesh="link_2.0"/>
                            <geom class="medial_collision" pos="0 0 0.0192" mass="0"/>
                            <body name="mf_distal" pos="0 0 0.0384">
                              <joint name="mfj3" class="distal" pos="0 0 0" axis="0 1 0"/>
                              <geom class="allegro_visual" mesh="link_3.0"/>
                              <geom class="distal_collision" pos="0 0 0.008" mass="0"/>
                              <body name="mf_tip">
                                <geom class="allegro_visual" pos="0 0 0.0267" material="allegro_white" mesh="link_3.0_tip"/>
                                <geom class="fingertip_collision" pos="0 0 0.019" mass="0"/>
                                <site name="mf_grasp" pos="0 0 0.029" size="0.003" rgba="0 1 0 1"/>
                              </body>
                            </body>
                          </body>
                        </body>
                      </body>
                      <body name="rf_base" pos="0 -0.0435 -0.001542" quat="0.999048 0.0436194 0 0">
                        <joint name="rfj0" class="base" pos="0 0 0" axis="0 0 1"/>
                        <geom class="allegro_visual" mesh="link_0.0"/>
                        <geom class="base_collision" pos="0 0 0.0082" mass="0"/>
                        <body name="rf_proximal" pos="0 0 0.0164">
                          <joint name="rfj1" class="proximal" pos="0 0 0" axis="0 1 0"/>
                          <geom class="allegro_visual" mesh="link_1.0"/>
                          <geom class="proximal_collision" pos="0 0 0.027" mass="0"/>
                          <body name="rf_medial" pos="0 0 0.054">
                            <joint name="rfj2" class="medial" pos="0 0 0" axis="0 1 0"/>
                            <geom class="allegro_visual" mesh="link_2.0"/>
                            <geom class="medial_collision" pos="0 0 0.0192" mass="0"/>
                            <body name="rf_distal" pos="0 0 0.0384">
                              <joint name="rfj3" class="distal" pos="0 0 0" axis="0 1 0"/>
                              <geom class="allegro_visual" mesh="link_3.0"/>
                              <geom class="distal_collision" pos="0 0 0.008" mass="0"/>
                              <body name="rf_tip">
                                <geom class="allegro_visual" pos="0 0 0.0267" material="allegro_white" mesh="link_3.0_tip"/>
                                <geom class="fingertip_collision" pos="0 0 0.019" mass="0"/>
                                <site name="rf_grasp" pos="0 0 0.029" size="0.003" rgba="0 0 1 1"/>
                              </body>
                            </body>
                          </body>
                        </body>
                      </body>
                      <body name="th_base" pos="-0.0182 0.019333 -0.045987" quat="0.477714 -0.521334 -0.521334 -0.477714">
                        <joint name="thj0" class="thumb_base" pos="0 0 0" axis="-1 0 0"/>
                        <geom class="allegro_visual" mesh="link_12.0_right"/>
                        <geom class="thumb_base_collision" pos="-0.0179 0.009 0.0145" mass="0"/>
                        <body name="th_proximal" pos="-0.027 0.005 0.0399">
                          <joint name="thj1" class="thumb_proximal" pos="0 0 0" axis="0 0 1"/>
                          <geom class="allegro_visual" mesh="link_13.0"/>
                          <geom class="thumb_proximal_collision" pos="0 0 0.00885" mass="0"/>
                          <body name="th_medial" pos="0 0 0.0177">
                            <joint name="thj2" class="thumb_medial" pos="0 0 0" axis="0 1 0"/>
                            <geom class="allegro_visual" mesh="link_14.0"/>
                            <geom class="thumb_medial_collision" pos="0 0 0.0257" mass="0"/>
                            <body name="th_distal" pos="0 0 0.0514">
                              <joint name="thj3" class="thumb_distal" pos="0 0 0" axis="0 1 0"/>
                              <geom class="allegro_visual" mesh="link_15.0"/>
                              <geom class="thumb_distal_collision" pos="0 0 0.0157" mass="0"/>
                              <body name="th_tip">
                                <geom class="allegro_visual" pos="0 0 0.0423" material="allegro_white" mesh="link_15.0_tip"/>
                                <geom class="thumbtip_collision" pos="0 0 0.035" mass="0"/>
                                <site name="th_grasp" pos="0 0 0.045" size="0.003" rgba="1 1 0 1"/>
                              </body>
                            </body>
                          </body>
                        </body>
                      </body>
                    </body>
                  </body>
                </body>
              </body>
            </body>
          </body>
        </body>
      </body>
    </body>
    <body name="rack" pos="0.55 0 0.5">
      <geom name="post_lf" class="obstacle" size="0.015 0.015 0.4" pos="-0.2 0.25 0" type="box" material="rack_metal"/>
      <geom name="post_rf" class="obstacle" size="0.015 0.015 0.4" pos="-0.2 -0.25 0" type="box" material="rack_metal"/>
      <geom name="post_lr" class="obstacle" size="0.015 0.015 0.4" pos="0.2 0.25 0" type="box" material="rack_metal"/>
      <geom name="post_rr" class="obstacle" size="0.015 0.015 0.4" pos="0.2 -0.25 0" type="box" material="rack_metal"/>
      <geom name="shelf_bottom" class="obstacle" size="0.2 0.25 0.01" pos="0 0 -0.25" type="box" material="rack_metal"/>
      <geom name="shelf_mid" class="obstacle" size="0.2 0.25 0.01" pos="0 0 0.05" type="box" material="rack_metal"/>
      <geom name="shelf_top" class="obstacle" size="0.2 0.25 0.01" pos="0 0 0.3" type="box" material="rack_metal"/>
      <geom name="cable_tray_1" class="obstacle" size="0.18 0.02 0.03" pos="0 0.2 -0.1" type="box" material="cable_tray"/>
      <geom name="conduit_1" class="obstacle" size="0.015 0.22" pos="0 0 0.15" quat="0.707107 0.707107 0 0" type="cylinder" material="cable_tray"/>
      <geom name="cable_bundle" class="obstacle" size="0.02 0.15" pos="0.1 -0.15 -0.05" quat="0.707107 0 0.707107 0" type="cylinder" material="cable_tray"/>
      <body name="target_object" pos="0.05 0 0.07">
        <geom name="target" size="0.025 0.02 0.02" type="box" contype="8" conaffinity="8" mass="0.1" material="target_obj"/>
      </body>
    </body>
  </worldbody>

  <contact>
    <exclude body1="base_link" body2="shoulder_link"/>
    <exclude body1="shoulder_link" body2="half_arm_1_link"/>
    <exclude body1="half_arm_1_link" body2="half_arm_2_link"/>
    <exclude body1="half_arm_2_link" body2="forearm_link"/>
    <exclude body1="forearm_link" body2="spherical_wrist_1_link"/>
    <exclude body1="spherical_wrist_1_link" body2="spherical_wrist_2_link"/>
    <exclude body1="spherical_wrist_2_link" body2="bracelet_link"/>
    <exclude body1="bracelet_link" body2="palm"/>
    <exclude body1="palm" body2="ff_base"/>
    <exclude body1="palm" body2="mf_base"/>
    <exclude body1="palm" body2="rf_base"/>
    <exclude body1="palm" body2="th_base"/>
    <exclude body1="palm" body2="th_proximal"/>
  </contact>

  <actuator>
    <general name="act_joint_1" class="large_actuator" joint="joint_1"/>
    <general name="act_joint_2" class="large_actuator" joint="joint_2" ctrlrange="-2.2497 2.2497"/>
    <general name="act_joint_3" class="large_actuator" joint="joint_3"/>
    <general name="act_joint_4" class="large_actuator" joint="joint_4" ctrlrange="-2.5796 2.5796"/>
    <general name="act_joint_5" class="small_actuator" joint="joint_5"/>
    <general name="act_joint_6" class="small_actuator" joint="joint_6" ctrlrange="-2.0996 2.0996"/>
    <general name="act_joint_7" class="small_actuator" joint="joint_7"/>
    <general name="ffa0" class="base" joint="ffj0"/>
    <general name="ffa1" class="proximal" joint="ffj1"/>
    <general name="ffa2" class="medial" joint="ffj2"/>
    <general name="ffa3" class="distal" joint="ffj3"/>
    <general name="mfa0" class="base" joint="mfj0"/>
    <general name="mfa1" class="proximal" joint="mfj1"/>
    <general name="mfa2" class="medial" joint="mfj2"/>
    <general name="mfa3" class="distal" joint="mfj3"/>
    <general name="rfa0" class="base" joint="rfj0"/>
    <general name="rfa1" class="proximal" joint="rfj1"/>
    <general name="rfa2" class="medial" joint="rfj2"/>
    <general name="rfa3" class="distal" joint="rfj3"/>
    <general name="tha0" class="thumb_base" joint="thj0"/>
    <general name="tha1" class="thumb_proximal" joint="thj1"/>
    <general name="tha2" class="thumb_medial" joint="thj2"/>
    <general name="tha3" class="thumb_distal" joint="thj3"/>
  </actuator>

  <keyframe>
    <key name="home" qpos="0 0.26 3.14 -2.27 0 0.96 1.57 0 0.3 0.3 0.3 0 0.3 0.3 0.3 0 0.3 0.3 0.3 0.83 0.53 0.3 0.3" ctrl="0 0.26 3.14 -2.27 0 0.96 1.57 0 0.3 0.3 0.3 0 0.3 0.3 0.3 0 0.3 0.3 0.3 0.3 0.4 1.3 0.3"/>
  </keyframe>
</mujoco>
